Workbook

Sheet Aktywa
A1: AKTYWA | B1: 2025 | C1: 2024 | D1: 2023 | E1: 2022
A3: Aktywa Dane w PLN | B3: Kwota na dzień | C3: Kwota na dzień | D3: Kwota na dzień
B4: kończący bieżący | C4: kończący poprzedni | D4: kończący poprzedni
B5: rok obrotowy | C5: rok obrotowy | D5: rok obrotowy
A6: A. AKTYWA TRWAŁE | B6: 367371.15 | C6: 459231.6 | D6: 183039.93
A7: I. Wartości niematerialne i prawne | B7: 72520.35 | C7: 169214.19 | D7: 0
A8: 1. Koszty zakończonych prac rozwojowych | B8: 0 | C8: 0 | D8: 0
A9: 2. Wartość firmy | B9: 0 | C9: 0 | D9: 0
A10: 3. Inne wartości niematerialne i prawne | B10: 72520.35 | C10: 169214.19 | D10: 0
A11: 4. Zaliczki na wartości niematerialne i prawne | B11: 0 | C11: 0 | D11: 0
A12: II. Rzeczowe aktywa trwałe | B12: 221033.32 | C12: 248609.71 | D12: 183039.93
A13: 1. Środki trwałe | B13: 221033.32 | C13: 236379.64 | D13: 183039.93
A14: a) grunty (w tym prawo użytkowania wieczystego gruntu) | B14: 0 | C14: 0 | D14: 0
A15: b) budynki, lokale, prawa do lokali i obiekty inżynierii | B15: 95828.4 | C15: 106885.56 | D15: 0
A16: lądowej i wodnej | B16: 0 | C16: 0 | D16: 0
A17: c) urządzenia techniczne i maszyny | B17: 23084.43 | C17: 27802.47 | D17: 51653.83
... A48: B. AKTYWA OBROTOWE | B48: 10068337 | C48: 8177289.1 | D48: 7472065.4
A49: I. Zapasy | B49: 4681502.7 | C49: 4410497.6 | D49: 2207709.5 | E49: 2853213.1
A50: 1. Materiały | B50: 0 | C50: 0 | D50: 0
A51: 2. Półprodukty i produkty w toku | B51: 0 | C51: 0 | D51: 0
A52: 3. Produkty gotowe | B52: 0 | C52: 0 | D52: 0
A53: 4. Towary | B53: 4346095.3 | C53: 4275390.5 | D53: 2199849.5
A54: 5. Zaliczki na dostawy i usługi | B54: 335407.38 | C54: 135107.14 | D54: 7860
A55: II. Należności krótkoterminowe | B55: 3281260.2 | C55: 2271501.5 | D55: 1925769
A56: 1. Należności od jednostek powiązanych | B56: 0 | C56: 0 | D56: 0
A57: a) z tytułu dostaw i usług, o okresie spłaty: | B57: 0 | C57: 0 | D57: 0
A58: - do 12 miesięcy | B58: 0 | C58: 0 | D58: 0
A59: - powyżej 12 miesięcy | B59: 0 | C59: 0 | D59: 0
A60: b) inne | B60: 0 | C60: 0 | D60: 0
A61: 2. Należności od pozostałych jednostek, w których jednostka posiada zaangażowanie w kapitale | B61: 0 | C61: 0 | D61: 0
... A66: 3. Należności od pozostałych jednostek | B66: 3281260.2 | C66: 2271501.5 | D66: 1925769
A67: a) z tytułu dostaw i usług, o okresie spłaty: | B67: 3071659.7 | C67: 2089774 | D67: 1809678.1 | E67: 246310.64
A68: - do 12 miesięcy | B68: 3071659.7 | C68: 2089774 | D68: 1809678.1
A69: - powyżej 12 miesięcy | B69: 0 | C69: 0 | D69: 0
A70: b) z tytułu podatków, dotacji, ceł, ubezpieczeń | B70: 59862.91 | C70: 70099.29 | D70: 6266.91
A71: społecznych i zdrowotnych oraz innych tytułów | B71: 0 | C71: 0 | D71: 0
A72: publicznoprawnych | B72: 0 | C72: 0 | D72: 0
A73: c) inne | B73: 149737.6 | C73: 111628.26 | D73: 109823.97
A74: d) dochodzone na drodze sądowej | B74: 0 | C74: 0 | D74: 0
A75: III. Inwestycje krótkoterminowe | B75: 2048805.8 | C75: 1402530.9 | D75: 3283346.1
...

Sheet Pasywa
A1: PASYWA | B1: 2025 | C1: 2024 | D1: 2023 | E1: 2022
A3: Pasywa Dane w PLN | B3: Kwota na dzień | C3: Kwota na dzień | D3: Kwota na dzień
B4: kończący bieżący | C4: kończący poprzedni | D4: kończący poprzedni
B5: rok obrotowy | C5: rok obrotowy | D5: rok obrotowy
A6: A. KAPITAŁ (FUNDUSZ) WŁASNY | B6: 8629975.5 | C6: 6333581.2 | D6: 5771091.7 | E6: 3756935.9
A7: I. Kapitał (fundusz) podstawowy | B7: 148478.6 | C7: 148478.6 | D7: 140372.7
A8: II. Kapitał (fundusz) zapasowy, w tym: | B8: 3957902.6 | C8: 5630719 | D8: 3616563.2
A9: - nadwyżka wartości sprzedaży (wartości emisyjnej) nad | B9: 2343648.8 | C9: 2343648.8 | D9: 2343648.8
A10: wartością nominalną udziałów (akcji) | B10: 0 | C10: 0 | D10: 0
A11: III. Kapitał (fundusz) z aktualizacji wyceny, w tym: | B11: 0 | C11: 0 | D11: 0
A12: - z tytułu aktualizacji wartości godziwej | B12: 0 | C12: 0 | D12: 0
A13: IV. Pozostałe kapitały (fundusze) rezerwowe | B13: 2227200 | C13: 0 | D13: 0
A14: - tworzone zgodnie z umową (statutem) spółki | B14: 0 | C14: 0 | D14: 0
A15: - na udziały (akcje) własne | B15: 2227200 | C15: 0 | D15: 0
A16: V. Zysk (strata) z lat ubiegłych | B16: 0 | C16: 0 | D16: 0
A17: VI. Zysk (strata) netto | B17: 2296394.3 | C17: 554383.64 | D17: 2014155.8
A18: VII. Odpisy z zysku netto w ciągu roku obrotowego (wielkość ujemna) | B18: 0 | C18: 0 | D18: 0
... A31: 3. Wobec pozostałych jednostek | B31: 0 | C31: 0 | D31: 0
A32: a) kredyty i pożyczki | B32: 0 | C32: 0 | D32: 0 | E32: 0
A33: b) z tytułu emisji dłużnych papierów wartościowych | B33: 0 | C33: 0 | D33: 0
A34: c) inne zobowiązania finansowe | B34: 0 | C34: 0 | D34: 0
A35: d) zobowiązania wekslowe | B35: 0 | C35: 0 | D35: 0
A36: e) inne | B36: 0 | C36: 0 | D36: 0
A37: III. Zobowiązania krótkoterminowe | B37: 2010475.2 | C37: 2252944.3 | D37: 1871847.3
A38: 1. Wobec jednostek powiązanych | B38: 0 | C38: 0 | D38: 0
A39: a) z tytułu dostaw i usług, o okresie wymagalności, w | B39: 0 | C39: 0 | D39: 0
A40: tym: | B40: 0 | C40: 0 | D40: 0
A41: - do 12 miesięcy | B41: 0 | C41: 0 | D41: 0
A42: - powyżej 12 miesięcy | B42: 0 | C42: 0 | D42: 0
A43: b) inne | B43: 0 | C43: 0 | D43: 0
A44: 2. Wobec pozostałych jednostek, w których jednostka posiada zaangażowanie w kapitale | B44: 0 | C44: 0 | D44: 0
... A49: 3. Wobec pozostałych jednostek | B49: 2010475.2 | C49: 2252944.3 | D49: 1871847.3
A50: a) kredyty i pożyczki | B50: 0 | C50: 60145.35 | D50: 0 | E50: 350750
A51: b) z tytułu emisji dłużnych papierów wartościowych | B51: 0 | C51: 0 | D51: 0
A52: c) inne zobowiązania finansowe | B52: 0 | C52: 0 | D52: 0
A53: d) z tytułu dostaw i usług, o okresie wymagalności: | B53: 1790707.1 | C53: 1990465.3 | D53: 1245359.5 | E53: 536386.76
A54: - do 12 miesięcy | B54: 1790707.1 | C54: 1990465.3 | D54: 1245359.5
A55: - powyżej 12 miesięcy | B55: 0 | C55: 0 | D55: 0
A56: e) zaliczki otrzymane na dostawy i usługi | B56: 0 | C56: 0 | D56: 0
A57: f) zobowiązania wekslowe | B57: 0 | C57: 0 | D57: 0
...

Sheet RZiS
A1: RACHUNEK ZYSKÓW I STRAT | B1: 2025 | C1: 2024 | D1: 2023
A3: Wariant porównawczy Dane w PLN | B3: Kwota za bieżący | C3: Kwota za poprzedni | D3: Kwota za poprzedni
B4: rok obrotowy | C4: rok obrotowy | D4: rok obrotowy
A5: A. Przychody netto ze sprzedaży i zrównane z nimi, w tym: | B5: 32029124 | C5: 22061763 | D5: 21733433
A6: - od jednostek powiązanych | B6: 0 | C6: 0 | D6: 0
A7: I. Przychody netto ze sprzedaży produktów | B7: 186363.45 | C7: 118669.41 | D7: 27000
A8: II. Zmiana stanu produktów (zwiększenie - wartość dodatnia, zmniejszenie - wartość ujemna) | B8: 0 | C8: 0 | D8: 0
A9: III. Koszt wytworzenia produktów na własne potrzeby jednostki | B9: 0 | C9: 0 | D9: 0
A10: IV. Przychody netto ze sprzedaży towarów | B10: 31842760 | C10: 21943094 | D10: 21706433
A11: B. Koszty działalności operacyjnej | B11: 28729404 | C11: 20892173 | D11: 19274942
A12: I. Amortyzacja | B12: 164727.92 | C12: 63205.03 | D12: 179467.65
A13: II. Zużycie materiałów i energii | B13: 418619.09 | C13: 406860.27 | D13: 420476.19
A14: III. Usługi obce | B14: 12034440 | C14: 9011131 | D14: 7982102.3
A15: IV. Podatki i opłaty, w tym: | B15: 29416.9 | C15: 4825.39 | D15: 30703.92
A16: - podatek akcyzowy | B16: 0 | C16: 0 | D16: 0
... A55: L. Zysk (strata) netto (I-J-K) | B55: 2296394.3 | C55: 554383.64 | D55: 2014155.8

Sheet RPP
A1: RACHUNEK PRZEPŁYWÓW PIENIĘŻNYCH | B1: 2025 | C1: 2024 | D1: 2023
A3: Metoda pośrednia Dane w PLN | B3: Kwota za bieżący | C3: Kwota za poprzedni | D3: Kwota za poprzedni
B4: rok obrotowy | C4: rok obrotowy | D4: rok obrotowy
A5: A. Przepływy środków pieniężnych z działalności operacyjnej | B5: 0 | C5: 0 | D5: 0
A6: I. Zysk (strata) netto | B6: 2296394.3 | C6: 554383.64 | D6: 2014155.8
A7: II. Korekty razem | B7: -1062494.8 | C7: -2248610.5 | D7: 283946.12
A8: 1. Amortyzacja | B8: 164727.92 | C8: 63205.03 | D8: 179467.65
A9: 2. Zyski (straty) z tytułu różnic kursowych | B9: 0 | C9: 0 | D9: 0
A10: 3. Odsetki i udziały w zyskach (dywidendy) | B10: 99595.82 | C10: 23694.72 | D10: 78191.78
A11: 4. Zysk (strata) z działalności inwestycyjnej | B11: 182603.5 | C11: -66844.1 | D11: -123033.53
A12: 5. Zmiana stanu rezerw | B12: -4030 | C12: 4030 | D12: 0
A13: 6. Zmiana stanu zapasów | B13: -271005.01 | C13: -2202788.1 | D13: 645503.59
A14: 7. Zmiana stanu należności | B14: -1009758.7 | C14: -345732.54 | D14: -1482653.8
A15: 8. Zmiana stanu zobowiązań krótkoterminowych, z | B15: -182323.75 | C15: 320951.59 | D15: 1020366.7
A16: wyjątkiem pożyczek i kredytów | B16: 0 | C16: 0 | D16: 0
... A46: III. Przepływy pieniężne netto z działalności inwestycyjnej | B46: -427654.73 | C46: -230820.57 | D46: 128470.33
B47: 0 | C47: 0 | D47: 0
A48: C. Przepływy środków pieniężnych z działalności finansowej | B48: 0 | C48: 0 | D48: 0
A49: I. Wpływy | B49: 2512295.9 | C49: 363730.62 | D49: 552612.68
A50: 1. Wpływy netto z wydania udziałów (emisji akcji) i innych | B50: 0 | C50: 8105.9 | D50: 0
A51: instrumentów kapitałowych oraz dopłat do kapitału | B51: 0 | C51: 0 | D51: 0
A52: 2. Kredyty i pożyczki | B52: 2512295.9 | C52: 355624.72 | D52: 552612.68
A53: 3. Emisja dłużnych papierów wartościowych | B53: 0 | C53: 0 | D53: 0
A54: 4. Inne wpływy finansowe | B54: 0 | C54: 0 | D54: 0
A55: II. Wydatki | B55: 2672265.7 | C55: 319498.42 | D55: 981554.46
A56: 1. Nabycie udziałów (akcji) własnych | B56: 0 | C56: 0 | D56: 0
A57: 2. Dywidendy i inne wypłaty na rzecz właścicieli | B57: 0 | C57: 0 | D57: 0
A58: 3. Inne, niż wypłaty na rzecz właścicieli, wydatki z tytułu podziału zysku | B58: 0 | C58: 0 | D58: 0
A59: 4. Spłaty kredytów i pożyczek | B59: 2572441.2 | C59: 295479.37 | D59: 903362.68
... A65: III. Przepływy pieniężne netto z działalności finansowej (I– | B65: -159969.83 | C65: 44232.2 | D65: -428941.78
B66: 0 | C66: 0 | D66: 0
A67: D. Przepływy pieniężne netto, razem | B67: 646274.93 | C67: -1880815.2 | D67: 1997630.5
A68: E. Bilansowa zmiana stanu środków pieniężnych, w tym: | B68: 646274.93 | C68: -1880815.2 | D68: 1997630.5
A69: - zmiana stanu środków pieniężnych z tytułu różnic kursowych | B69: 0 | C69: 0 | D69: 0
A70: F. Środki pieniężne na początek okresu | B70: 1402530.9 | C70: 3283346.1 | D70: 1285715.6
A71: G. Środki pieniężne na koniec okresu, w tym: | B71: 2048805.8 | C71: 1402530.9 | D71: 3283346.1
A72: - o ograniczonej możliwości dysponowania | B72: 13436.1 | C72: 12157.45 | D72: 3644.56

Sheet Wskaźniki
C2: 2025 | D2: 2024 | E2: 2023
B3: PŁYNNOŚĆ FINANSOWA
B4: Płynność bieżąca | C4: =Aktywa!B48/Pasywa!B37 -> 5.0079391 | D4: =Aktywa!C48/Pasywa!C37 -> 3.6296011 | E4: =Aktywa!D48/Pasywa!D37 -> 3.9918135
B5: Płynność szybka | C5: =(Aktywa!B48-Aktywa!B49)/Pasywa!B37 -> 2.6793838 | D5: =(Aktywa!C48-Aktywa!C49)/Pasywa!C37 -> 1.6719417 | E5: =(Aktywa!D48-Aktywa!D49)/Pasywa!D37 -> 2.8123853
B6: Wskaźnik gotówkowy | C6: =Aktywa!B87/Pasywa!B37 -> 1.0190655 | D6: =Aktywa!C87/Pasywa!C37 -> 0.62253244 | E6: =Aktywa!D87/Pasywa!D37 -> 1.7540673
B7: Kapitał obrotowy netto | C7: =Aktywa!B48-Pasywa!B37 -> 8057862.1 | D7: =Aktywa!C48-Pasywa!C37 -> 5924344.8 | E7: =Aktywa!D48-Pasywa!D37 -> 5600218.1
B9: RENTOWNOŚĆ
B10: Marża brutto | C10: =('RZiS'!B10-'RZiS'!B21)/'RZiS'!B10 -> 0.52114829 | D10: =('RZiS'!C10-'RZiS'!C21)/'RZiS'!C10 -> 0.5196302 | E10: =('RZiS'!D10-'RZiS'!D21)/'RZiS'!D10 -> 0.54769257 | G10: *przybliżenie!
B11: Marża operacyjna EBIT | C11: ='RZiS'!B32/'RZiS'!B5 -> 0.10125746 | D11: ='RZiS'!C32/'RZiS'!C5 -> 0.044418976 | E11: ='RZiS'!D32/'RZiS'!D5 -> 0.11141175
B12: Marża netto (ROS) | C12: ='RZiS'!B55/'RZiS'!B5 -> 0.071697068 | D12: ='RZiS'!C55/'RZiS'!C5 -> 0.025128709 | E12: ='RZiS'!D55/'RZiS'!D5 -> 0.092675455
B13: ROA | C13: ='RZiS'!B55/((Aktywa!B95+Aktywa!C95)/2) -> 0.23825161 | D13: ='RZiS'!C55/((Aktywa!C95+Aktywa!D95)/2) -> 0.068057496 | E13: ='RZiS'!D55/((Aktywa!D95+Aktywa!E95)/2) -> 0.31845587
B14: ROE | C14: ='RZiS'!B55/((Pasywa!B6+Pasywa!C6)/2) -> 0.30693161 | D14: ='RZiS'!C55/((Pasywa!C6+Pasywa!D6)/2) -> 0.091598285 | E14: ='RZiS'!D55/((Pasywa!D6+Pasywa!E6)/2) -> 0.42278547
B15: ROIC | C15: =('RZiS'!B32*(1-'RZiS'!B53/'RZiS'!B52))/(((Pasywa!B6+Pasywa!B32+Pasywa!B50)+(Pasywa!C6+Pasywa!C32+Pasywa!C50))/2) -> 0.34974429 | D15: =('RZiS'!C32*(1-'RZiS'!C53/'RZiS'!C52))/(((Pasywa!C6+Pasywa!C32+Pasywa!C50)+(Pasywa!D6+Pasywa!D32+Pasywa!D50))/2) -> 0.13141503 | E15: =('RZiS'!D32*(1-'RZiS'!D53/'RZiS'!D52))/(((Pasywa!D6+Pasywa!D32+Pasywa!D50)+(Pasywa!E6+Pasywa!E32+Pasywa!E50))/2) -> 0.39035566
B17: ZADŁUŻENIE I WYPŁACALNOŚĆ
B18: D/E (dług/kap. Własny) | C18: =Pasywa!B19/Pasywa!B6 -> 0.23297345 | D18: =Pasywa!C19/Pasywa!C6 -> 0.36360779 | E18: =Pasywa!D19/Pasywa!D6 -> 0.32645706
B19: Dług netto / EBITDA | C19: =(Pasywa!B50+Pasywa!B32-Aktywa!B87)/('RZiS'!B32+'RZiS'!B12) -> -0.60119031 | D19: =(Pasywa!C50+Pasywa!C32-Aktywa!C87)/('RZiS'!C32+'RZiS'!C12) -> -1.2868379 | E19: =(Pasywa!D50+Pasywa!D32-Aktywa!D87)/('RZiS'!D32+'RZiS'!D12) -> -1.2624237
B20: Wskaźnik pokrycia odsetek | C20: ='RZiS'!B32/'RZiS'!B46 -> 32.488901 | D20: ='RZiS'!C32/'RZiS'!C46 -> 40.799321 | E20: ='RZiS'!D32/'RZiS'!D46 -> 30.966935
B21: Wskaźnik ogólnego zadłużenia | C21: =Pasywa!B19/Aktywa!B95 -> 0.18895253 | D21: =Pasywa!C19/Aktywa!C95 -> 0.2666513 | E21: =Pasywa!D19/Aktywa!D95 -> 0.24611205
B23: SPRAWNOŚĆ / EFEKTYWNOSC OPERACYJNA
B24: Rotacja należności | C24: =((Aktywa!B67+Aktywa!C67)/2)/'RZiS'!B5*1.23*365 -> 36.173729 | D24: =((Aktywa!C67+Aktywa!D67)/2)/'RZiS'!C5*1.23*365 -> 39.676317 | E24: =((Aktywa!D67+Aktywa!E67)/2)/'RZiS'!D5*1.23*365 -> 21.235397
B25: Rotacja zapasów | C25: =(Aktywa!B49+Aktywa!C49)/2/'RZiS'!B21*365 -> 108.82046 | D25: =(Aktywa!C49+Aktywa!D49)/2/'RZiS'!C21*365 -> 114.5855 | E25: =(Aktywa!D49+Aktywa!E49)/2/'RZiS'!D21*365 -> 94.074166
B26: Rotacja zobowiązań | C26: =((Pasywa!B53+Pasywa!C53)/2)/'RZiS'!B21*365 -> 45.256148 | D26: =((Pasywa!C53+Pasywa!D53)/2)/'RZiS'!C21*365 -> 56.024025 | E26: =((Pasywa!D53+Pasywa!E53)/2)/'RZiS'!D21*365 -> 33.119711
B27: Cykl konwersji gotówki | C27: =C24+C25-C26 -> 99.738041 | D27: =D24+D25-D26 -> 98.237793 | E27: =E24+E25-E26 -> 82.189852
B28: Rotacja aktywów | C28: ='RZiS'!B5/((Aktywa!B95+Aktywa!C95)/2) -> 3.3230314 | D28: ='RZiS'!C5/((Aktywa!C95+Aktywa!D95)/2) -> 2.7083562 | E28: ='RZiS'!D5/((Aktywa!D95+Aktywa!E95)/2) -> 3.4362482

Sheet Wykresy
B3: WYKRESY TRENDU
B5: Rok | C5: Przychody (PLN) | D5: Marża netto | E5: Płynność bieżąca | F5: Płynność szybka | G5: Wskaźnik gotówkowy | H5: Próg bezp. (1.0) | I5: Dług netto/EBITDA
B6: 2023 | C6: ='RZiS'!D5 -> 21733433 | D6: =Wskaźniki!E12 -> 0.092675455 | E6: =Wskaźniki!E4 -> 3.9918135 | F6: =Wskaźniki!E5 -> 2.8123853 | G6: =Wskaźniki!E6 -> 1.7540673 | H6: 1 | I6: =Wskaźniki!E19 -> -1.2624237
B7: 2024 | C7: ='RZiS'!C5 -> 22061763 | D7: =Wskaźniki!D12 -> 0.025128709 | E7: =Wskaźniki!D4 -> 3.6296011 | F7: =Wskaźniki!D5 -> 1.6719417 | G7: =Wskaźniki!D6 -> 0.62253244 | H7: 1 | I7: =Wskaźniki!D19 -> -1.2868379
B8: 2025 | C8: ='RZiS'!B5 -> 32029124 | D8: =Wskaźniki!C12 -> 0.071697068 | E8: =Wskaźniki!C4 -> 5.0079391 | F8: =Wskaźniki!C5 -> 2.6793838 | G8: =Wskaźniki!C6 -> 1.0190655 | H8: 1 | I8: =Wskaźniki!C19 -> -0.60119031
